Workbook

Sheet База ставок
A1: Показатель | B1: Значение | C1: Основание
A2: Медианная зарплата Middle системного аналитика, ₽/мес до НДФЛ | B2: 204441 | C2: Хабр Карьера, страница «Системный аналитик, Middle», 1 219 анкет; сверено 2026-09-05
A3: Медианная зарплата Middle бэкенд-разработчика, ₽/мес до НДФЛ | B3: 220833 | C3: Хабр Карьера, страница «Бэкенд разработчик, Middle», 3 449 анкет; сверено 2026-09-05
A4: Ставка страховых взносов работодателя | B4: 0.3 | C4: Единый тариф 30 % до предельной базы; для аккредитованной ИТ-компании ставится 7,6 %
A5: Годовая норма рабочего времени, ч | B5: 1972 | C5: Производственный календарь 2026, 40-часовая неделя, 247 рабочих дней
A6: Среднемесячная норма рабочего времени, ч | B6: =B5/12 -> 164.33333 | C6: Годовая норма, делённая на 12
A7: Стоимость часа аналитика | B7: =ROUND(B2*(1+B4)/B6,0) -> 1617 | C7: Зарплата с взносами, делённая на месячную норму часов
A8: Стоимость часа разработчика | B8: =ROUND(B3*(1+B4)/B6,0) -> 1747 | C8: Зарплата с взносами, делённая на месячную норму часов
A9: Медианная зарплата Middle DevOps-инженера, ₽/мес до НДФЛ | B9: 230500 | C9: Хабр Карьера, страница «DevOps-инженер, Middle»; сверено 2026-09-06
A10: Стоимость часа DevOps-инженера | B10: =ROUND(B9*(1+B4)/B6,0) -> 1823 | C10: Зарплата с взносами, делённая на месячную норму часов
A12: Стоимость часа = медианная зарплата × (1 + ставка взносов) ÷ среднемесячная норма часов. Это полная стоимость часа для работодателя, а не выплата сотруднику.
A13: Премии, накладные расходы, отпускные сверх нормы и региональные надбавки в расчёт не входят.
A14: Значения являются рыночными медианами, а не подтверждёнными ставками MTS. Разбор и ограничения — knowledge/economics.md.

Sheet Исходные данные
A1: Показатель | B1: Значение
A2: ТЗ на разработку/доработку, шт. | B2: 10
A3: Доля ТЗ, попадающих на повторное ревью | B3: 0.4
A4: Первичное ревью: трудозатраты аналитика, ч | B4: 2
A5: Первичное ревью: трудозатраты разработчика, ч | B5: 0
A6: Повторное ревью: трудозатраты аналитика, ч | B6: 2
A7: Повторное ревью: трудозатраты разработчика, ч | B7: 1
A8: Стоимость часа аналитика | B8: ='База ставок'!B7 -> 1617
A9: Стоимость часа разработчика | B9: ='База ставок'!B8 -> 1747
A10: Сокращение трудозатрат аналитика на ревью | B10: 0.3
A11: Сокращение трудозатрат разработчика на ревью | B11: 0.3
A12: Сокращение доли повторных ревью | B12: 0.75
A14: Первичное ревью автор делает сам, поэтому трудозатраты разработчика на нём равны нулю.
A15: Разработчик появляется только на повторном ревью: он обнаружил неясность и вернул ТЗ.

Sheet Экономический эффект
A1: Показатель (мес.) | B1: До | C1: После
A2: ТЗ на разработку/доработку, шт. | B2: ='Исходные данные'!B2 -> 10 | C2: =B2 -> 10
A3: Стоимость часа аналитика | B3: ='Исходные данные'!B8 -> 1617 | C3: =B3 -> 1617
A4: Стоимость часа разработчика | B4: ='Исходные данные'!B9 -> 1747 | C4: =B4 -> 1747
A6: ПЕРВИЧНОЕ РЕВЬЮ (проходят все ТЗ)
A7: Трудозатраты аналитика, ч | B7: ='Исходные данные'!B4 -> 2 | C7: =(1-'Исходные данные'!B10)*B7 -> 1.4
A8: Трудозатраты разработчика, ч | B8: ='Исходные данные'!B5 -> 0 | C8: =(1-'Исходные данные'!B11)*B8 -> 0
A9: Стоимость одного первичного ревью | B9: =B7*B3+B8*B4 -> 3234 | C9: =C7*C3+C8*C4 -> 2263.8
A10: ТЗ, шт. | B10: =B2 -> 10 | C10: =C2 -> 10
A11: Затраты на первичное ревью, ₽/мес | B11: =B10*B9 -> 32340 | C11: =C10*C9 -> 22638
A13: ПОВТОРНОЕ РЕВЬЮ (только возвращённые ТЗ)
A14: Доля ТЗ на повторное ревью | B14: ='Исходные данные'!B3 -> 0.4 | C14: =B14*(1-'Исходные данные'!B12) -> 0.1
A15: Трудозатраты аналитика, ч | B15: ='Исходные данные'!B6 -> 2 | C15: =(1-'Исходные данные'!B10)*B15 -> 1.4
A16: Трудозатраты разработчика, ч | B16: ='Исходные данные'!B7 -> 1 | C16: =(1-'Исходные данные'!B11)*B16 -> 0.7
A17: Стоимость одного повторного ревью | B17: =B15*B3+B16*B4 -> 4981 | C17: =C15*C3+C16*C4 -> 3486.7
A18: ТЗ, шт. | B18: =B2*B14 -> 4 | C18: =C2*C14 -> 1
A19: Затраты на повторное ревью, ₽/мес | B19: =B18*B17 -> 19924 | C19: =C18*C17 -> 3486.7
A21: ИТОГО
A22: Итого затраты на ревью, ₽/мес | B22: =B11+B19 -> 52264 | C22: =C11+C19 -> 26124.7
A23: Эффект, ₽/мес | C23: =B22-C22 -> 26139.3
A24: Эффект, ₽/год | C24: =C23*12 -> 313671.6
A26: Часы аналитика, ч/мес | B26: =B10*B7+B18*B15 -> 28 | C26: =C10*C7+C18*C15 -> 15.4
A27: Часы разработчика, ч/мес | B27: =B10*B8+B18*B16 -> 4 | C27: =C10*C8+C18*C16 -> 0.7
A28: Итого часов команды, ч/мес | B28: =B26+B27 -> 32 | C28: =C26+C27 -> 16.1
A29: Высвобождается часов, ч/мес | C29: =B28-C28 -> 15.9
A30: Высвобождается часов, ч/год | C30: =C29*12 -> 190.8
A32: Как устроен расчёт
A33: До внедрения каждое ТЗ проходит первичное ревью перед отправкой разработчику. Его делает автор, поэтому трудозатраты разработчика на этом проходе равны нулю.
A34: Часть ТЗ разработчик возвращает. Повторное ревью стоит дороже первичного, потому что к часам аналитика добавляются часы разработчика, который обнаружил неясность и описал её.
A35: После внедрения инструмент действует на два показателя сразу: одно ревью обходится дешевле и доля ТЗ, попадающих на повторное ревью, сокращается.
A36: Время аналитика на запуск проверки и разбор отчёта отдельной строкой не выделено — оно учтено внутри сокращения трудозатрат, то есть сокращение является чистым, за вычетом новой работы с отчётом.
A38: Статус значений
A39: Сокращение трудозатрат на ревью и сокращение доли повторных ревью являются условными допущениями, а не измерениями. Они подлежат замене результатами тестовых замеров ревью до и после.
A40: Расчёт не учитывает стоимость вычислительных ресурсов, поддержку профиля проверок, внедрение и изменение регламента, а также стоимость самой задержки разработки.
A41: Разбор модели и её ограничения — knowledge/economics.md.

Sheet Внедрение и эксплуатация
A1: Показатель | B1: Значение | C1: Основание
A2: ЦЕНЫ (публичные прайсы МТС и рыночные медианы)
A3: Цена 1 vCPU, ₽/мес | B3: 821.376 | C3: MWS Cloud Platform, тариф base с 01.08.2026, цена за месяц с НДС 22 %
A4: Цена 1 ГБ RAM, ₽/мес | B4: 230.688 | C4: MWS Cloud Platform, тариф base с 01.08.2026, цена за месяц с НДС 22 %
A5: Цена 1 ГБ диска NBS-PL2, ₽/мес | B5: 8.928 | C5: MWS Cloud Platform, тариф base с 01.08.2026, цена за месяц с НДС 22 %
A6: Справочно: цена 1 млн входных токенов, ₽ | B6: 70.76 | C6: MWS GPT Model Hub, модель qwen3.6-35b-a3b, с НДС 22 %. Справочно: платный инференс не используется
A7: Справочно: цена 1 млн выходных токенов, ₽ | B7: 283.04 | C7: MWS GPT Model Hub, модель qwen3.6-35b-a3b, с НДС 22 %. Справочно: платный инференс не используется
A8: Стоимость часа DevOps-инженера, ₽ | B8: ='База ставок'!B10 -> 1823 | C8: Медиана Middle DevOps с взносами, вкладка «База ставок»
A9: Стоимость часа аналитика, ₽ | B9: ='База ставок'!B7 -> 1617 | C9: Медиана Middle системного аналитика с взносами, вкладка «База ставок»
A11: КОНФИГУРАЦИЯ РАЗВЁРНУТОГО РЕШЕНИЯ
A12: vCPU, шт. | B12: 4 | C12: Одна ВМ на веб, API, обработчик и базу. Модель на этой машине не работает. Допущение при нагрузке в 10 ТЗ в месяц
A13: RAM, ГБ | B13: 8 | C13: Допущение
A14: Диск, ГБ | B14: 100 | C14: Документы, отчёты и база запусков. Допущение
A15: Прогонов ревью в месяц, шт. | B15: 15 | C15: 10 ТЗ из «Исходных данных» плюс повторные прогоны после правок. Допущение
A16: Справочно: входных токенов на прогон, тыс. | B16: 40 | C16: Документ 10 страниц с контекстом и профилем проходит через модель дважды: work items с перекрытием и synthesis
A17: Справочно: выходных токенов на прогон, тыс. | B17: 10 | C17: Замечания с цитатами и промежуточные ответы
A19: ВНЕДРЕНИЕ (единовременно, силами МТС)
A20: Согласование с ИБ и заведение сервиса в контур, ч | B20: 32 | C20: Единственное допущение расчёта: 80 часов трудозатрат МТС. Ориентир — оценка кейсодателя «месяц» на интеграцию MCP-сервера в закрытый контур
A21: Подключение к LLM команды и проверка сценария, ч | B21: 24 | C21: Часть тех же 80 часов. Модель не разворачивается: инструмент встраивается в существующий workflow команды с её LLM
A22: Настройка профиля проверки и контекста проекта, ч | B22: 16 | C22: Часть тех же 80 часов. Кто это делает на практике — открытый вопрос D-16
A23: Дополнение регламента разработки ТЗ и обучение команды, ч | B23: 8 | C23: Часть тех же 80 часов. Необходимость дополнения регламента — D-15
A24: Итого часов | B24: =SUM(B20:B23) -> 80
A25: Итого внедрение, ₽ | B25: =(B20+B21)*B8+(B22+B23)*B9 -> 140896 | C25: Часы ИБ и подключения по ставке DevOps, настройка и регламент — по ставке аналитика
A27: ЭКСПЛУАТАЦИЯ (ежемесячно)
A28: Инфраструктура, ₽/мес | B28: =B12*B3+B13*B4+B14*B5 -> 6023.808 | C28: ВМ под сам сервис ревью по публичному прайсу MWS. Не зависит от того, где работает модель
A29: Инференс LLM, ₽/мес | B29: 0 | C29: Ноль: инструмент работает на уже развёрнутой LLM команды, отдельная модель не разворачивается. Возникает нагрузка на существующий контур, а не платёж
A30: Справочно: инференс при платной модели, ₽/мес | B30: =B15*(B16*B6+B17*B7)/1000 -> 84.912 | C30: Во что обошёлся бы тот же объём прогонов по прайсу MWS GPT. В итог не входит
A31: Сопровождение DevOps, ч/мес | B31: 2 | C31: Обновления сервиса и зависимостей, мониторинг работоспособности, разбор инцидентов. Сокращено до 2 ч 2026-09-06. Допущение
A32: Поддержка профиля и контекста аналитиком, ч/мес | B32: 2 | C32: Перенос изменений шаблона документации и контекста проекта (справочники НСИ, соглашения по полям, схемы источников) в профиль проверки. Допущение
A33: Сопровождение, ₽/мес | B33: =B31*B8+B32*B9 -> 6880
A34: Итого эксплуатация, ₽/мес | B34: =B28+B29+B33 -> 12903.808
A35: Итого эксплуатация, ₽/год | B35: =B34*12 -> 154845.7
A37: СВОДКА ПО ОДНОЙ КОМАНДЕ
A38: Валовый эффект от ревью, ₽/мес | B38: ='Экономический эффект'!C23 -> 26139.3 | C38: Вкладка «Экономический эффект»
A39: Чистый эффект, ₽/мес | B39: =B38-B34 -> 13235.492 | C39: Валовый эффект за вычетом эксплуатации
A40: Чистый эффект, ₽/год | B40: =B39*12 -> 158825.9
A41: Окупаемость внедрения, мес | B41: =B25/B39 -> 10.645316 | C41: Затраты на внедрение, делённые на чистый эффект за месяц
A42: Итог первого года, ₽ | B42: =B40-B25 -> 17929.904 | C42: Годовой чистый эффект минус разовые затраты на внедрение
A44: РЕНТАБЕЛЬНОСТЬ ИНВЕСТИЦИЙ
A45: Валовый эффект за год, ₽ | B45: =B38*12 -> 313671.6
...
